Workbook

Sheet Results
A1: Student ID | B1: Assessment Type | C1: Score (1-100) | D1: Feedback Comment | E1: SILO's | F1: Weight | G1: Weighted Score
A2: STU0001 | B2: CSE1OOF - Test | C2: 54 | D2: This developing result meets the core requirements but needs greater consistency of the relevant learning themes, particularly analysis/design/implementation compared with object-oriented modelling using objects that combine data structure and behaviour and abstract data types and encapsulation to localise and minimise change. Future work should focus on consolidating the underlying concepts, applying them more consistently and explaining design or implementation decisions with stronger evidence. | E2: SILO1: analysis/design/implementation compared with object-oriented modelling using objects that combine data structure and behaviour; SILO2: abstract data types and encapsulation to localise and minimise change | F2: 0.15 | G2: =C2*F2 -> 8.1
A3: STU0001 | B3: CSE1OOF - Practical demonstration | C3: 49 | D3: This limited result shows gaps that require targeted revision of the relevant learning themes, particularly abstract data types and encapsulation to localise and minimise change, code sharing and reuse through object-oriented techniques to reduce development time, and object-oriented design and implementation of computer programs for real-life problems. The student should revisit the core concepts, seek feedback early and practise applying the techniques in smaller, well-tested examples before attempting the full assessment task. | E3: SILO2: abstract data types and encapsulation to localise and minimise change; SILO3: code sharing and reuse through object-oriented techniques to reduce development time; SILO4: object-oriented design and implementation of computer programs for real-life problems | F3: 0.2 | G3: =C3*F3 -> 9.8
A4: STU0001 | B4: CSE1OOF - Assignment | C4: 51 | D4: This developing result meets the core requirements but needs greater consistency of the relevant learning themes, particularly abstract data types and encapsulation to localise and minimise change, code sharing and reuse through object-oriented techniques to reduce development time, and object-oriented design and implementation of computer programs for real-life problems. Future work should focus on consolidating the underlying concepts, applying them more consistently and explaining design or implementation decisions with stronger evidence. | E4: SILO2: abstract data types and encapsulation to localise and minimise change; SILO3: code sharing and reuse through object-oriented techniques to reduce development time; SILO4: object-oriented design and implementation of computer programs for real-life problems | F4: 0.25 | G4: =C4*F4 -> 12.75
A5: STU0001 | B5: CSE1OOF - Central examination | C5: 50 | D5: This developing result meets the core requirements but needs greater consistency of the relevant learning themes, particularly abstract data types and encapsulation to localise and minimise change, object-oriented design and implementation of computer programs for real-life problems, code sharing and reuse through object-oriented techniques to reduce development time, and analysis/design/implementation compared with object-oriented modelling using objects that combine data structure and behaviour. Future work should focus on consolidating the underlying concepts, applying them more consistently and explaining design or implementation decisions with stronger evidence. | E5: SILO2: abstract data types and encapsulation to localise and minimise change; SILO4: object-oriented design and implementation of computer programs for real-life problems; SILO3: code sharing and reuse through object-oriented techniques to reduce development time; SILO1: analysis/design/implementation compared with object-oriented modelling using objects that combine data structure and behaviour | F5: 0.4 | G5: =C5*F5 -> 20
A6: STU0001 | B6: CSE2ALG - Test | C6: 53 | D6: This developing result meets the core requirements but needs greater consistency of the relevant learning themes, particularly overall objectives of Algorithms and Data Structures, identifying data structures and searching and sorting algorithms in computing contexts, and implementing data structures and searching and sorting algorithms in Java. Future work should focus on consolidating the underlying concepts, applying them more consistently and explaining design or implementation decisions with stronger evidence. | E6: SILO1: overall objectives of Algorithms and Data Structures; SILO2: identifying data structures and searching and sorting algorithms in computing contexts; SILO3: implementing data structures and searching and sorting algorithms in Java | F6: 0.2 | G6: =C6*F6 -> 10.6
A7: STU0001 | B7: CSE2ALG - Assignment | C7: 54 | D7: This developing result meets the core requirements but needs greater consistency of the relevant learning themes, particularly identifying data structures and searching and sorting algorithms in computing contexts, implementing data structures and searching and sorting algorithms in Java, comparing algorithms and data structures and applying suitable choices to problems, and designing, implementing, and evaluating Java solutions using appropriate performance measures. Future work should focus on consolidating the underlying concepts, applying them more consistently and explaining design or implementation decisions with stronger evidence. | E7: SILO2: identifying data structures and searching and sorting algorithms in computing contexts; SILO3: implementing data structures and searching and sorting algorithms in Java; SILO4: comparing algorithms and data structures and applying suitable choices to problems; SILO5: designing, implementing, and evaluating Java solutions using appropriate performance measures | F7: 0.3 | G7: =C7*F7 -> 16.2
A8: STU0001 | B8: CSE2ALG - Central examination | C8: 48 | D8: This limited result shows gaps that require targeted revision of the relevant learning themes, particularly overall objectives of Algorithms and Data Structures, identifying data structures and searching and sorting algorithms in computing contexts, implementing data structures and searching and sorting algorithms in Java, and designing, implementing, and evaluating Java solutions using appropriate performance measures. The student should revisit the core concepts, seek feedback early and practise applying the techniques in smaller, well-tested examples before attempting the full assessment task. | E8: SILO1: overall objectives of Algorithms and Data Structures; SILO2: identifying data structures and searching and sorting algorithms in computing contexts; SILO3: implementing data structures and searching and sorting algorithms in Java; SILO5: designing, implementing, and evaluating Java solutions using appropriate performance measures | F8: 0.5 | G8: =C8*F8 -> 24
A9: STU0001 | B9: CSE3CAP - Oral presentation: Project Milestone Presentation | C9: 50 | D9: This developing result meets the core requirements but needs greater consistency of the relevant learning themes, particularly reporting project outcomes to technical and non-technical audiences and reflecting on feedback. Future work should focus on consolidating the underlying concepts, applying them more consistently and explaining design or implementation decisions with stronger evidence. | E9: SILO3: reporting project outcomes to technical and non-technical audiences and reflecting on feedback | F9: 0.1 | G9: =C9*F9 -> 5
A10: STU0001 | B10: CSE3CAP - Oral presentation: Final Project Presentation | C10: 49 | D10: This limited result shows gaps that require targeted revision of the relevant learning themes, particularly reporting project outcomes to technical and non-technical audiences and reflecting on feedback. The student should revisit the core concepts, seek feedback early and practise applying the techniques in smaller, well-tested examples before attempting the full assessment task. | E10: SILO3: reporting project outcomes to technical and non-technical audiences and reflecting on feedback | F10: 0.2 | G10: =C10*F10 -> 9.8
A11: STU0001 | B11: CSE3CAP - Assignment: Final written Project Report | C11: 50 | D11: This developing result meets the core requirements but needs greater consistency of the relevant learning themes, particularly industry standard technical solutions in software or cybersecurity practice and professional system documentation and advanced technical reporting to industry standards. Future work should focus on consolidating the underlying concepts, applying them more consistently and explaining design or implementation decisions with stronger evidence. | E11: SILO2: industry standard technical solutions in software or cybersecurity practice; SILO4: professional system documentation and advanced technical reporting to industry standards | F11: 0.35 | G11: =C11*F11 -> 17.5
A12: STU0001 | B12: CSE3CAP - Assignment: Sprint Project management reports | C12: 46 | D12: This limited result shows gaps that require targeted revision of the relevant learning themes, particularly advanced project management during substantive development implementation and industry standard technical solutions in software or cybersecurity practice. The student should revisit the core concepts, seek feedback early and practise applying the techniques in smaller, well-tested examples before attempting the full assessment task. | E12: SILO1: advanced project management during substantive development implementation; SILO2: industry standard technical solutions in software or cybersecurity practice | F12: 0.35 | G12: =C12*F12 -> 16.1
A13: STU0002 | B13: CSE1OOF - Test | C13: 69 | D13: This sound result shows a competent and generally reliable grasp of the relevant learning themes, particularly analysis/design/implementation compared with object-oriented modelling using objects that combine data structure and behaviour and abstract data types and encapsulation to localise and minimise change. To strengthen the result, the student should provide clearer reasoning, improve technical precision and show more complete testing or reflection. | E13: SILO1: analysis/design/implementation compared with object-oriented modelling using objects that combine data structure and behaviour; SILO2: abstract data types and encapsulation to localise and minimise change | F13: 0.15 | G13: =C13*F13 -> 10.35
... A1651: STU0150 | B1651: CSE3CAP - Assignment: Sprint Project management reports | C1651: 85 | D1651: This excellent result demonstrates confident and independent command of the relevant learning themes, particularly advanced project management during substantive development implementation and industry standard technical solutions in software or cybersecurity practice. The work is clear, accurate and well justified, with only minor opportunities to further polish explanation or evaluation. | E1651: SILO1: advanced project management during substantive development implementation; SILO2: industry standard technical solutions in software or cybersecurity practice | F1651: 0.35 | G1651: =C1651*F1651 -> 29.75

Sheet Student Summary
A1: Student ID | B1: CSE1OOF Total | C1: CSE2ALG Total | D1: CSE3CAP Total | E1: Average Total | F1: Performance Band
A2: STU0001 | B2: =SUM(Results!G2:G5) -> 50.65 | C2: =SUM(Results!G6:G8) -> 50.8 | D2: =SUM(Results!G9:G12) -> 48.4 | E2: =AVERAGE(B2:D2) -> 49.95 | F2: =IF(E2>=80,"HD/D range",IF(E2>=70,"D range",IF(E2>=60,"C range",IF(E2>=50,"P range","At risk")))) -> At risk
A3: STU0002 | B3: =SUM(Results!G13:G16) -> 71.2 | C3: =SUM(Results!G17:G19) -> 71 | D3: =SUM(Results!G20:G23) -> 65.7 | E3: =AVERAGE(B3:D3) -> 69.3 | F3: =IF(E3>=80,"HD/D range",IF(E3>=70,"D range",IF(E3>=60,"C range",IF(E3>=50,"P range","At risk")))) -> C range
A4: STU0003 | B4: =SUM(Results!G24:G27) -> 62.65 | C4: =SUM(Results!G28:G30) -> 64.1 | D4: =SUM(Results!G31:G34) -> 65.4 | E4: =AVERAGE(B4:D4) -> 64.05 | F4: =IF(E4>=80,"HD/D range",IF(E4>=70,"D range",IF(E4>=60,"C range",IF(E4>=50,"P range","At risk")))) -> C range
A5: STU0004 | B5: =SUM(Results!G35:G38) -> 52.6 | C5: =SUM(Results!G39:G41) -> 48 | D5: =SUM(Results!G42:G45) -> 54.6 | E5: =AVERAGE(B5:D5) -> 51.733333 | F5: =IF(E5>=80,"HD/D range",IF(E5>=70,"D range",IF(E5>=60,"C range",IF(E5>=50,"P range","At risk")))) -> P range
A6: STU0005 | B6: =SUM(Results!G46:G49) -> 73.15 | C6: =SUM(Results!G50:G52) -> 73.9 | D6: =SUM(Results!G53:G56) -> 73.75 | E6: =AVERAGE(B6:D6) -> 73.6 | F6: =IF(E6>=80,"HD/D range",IF(E6>=70,"D range",IF(E6>=60,"C range",IF(E6>=50,"P range","At risk")))) -> D range
A7: STU0006 | B7: =SUM(Results!G57:G60) -> 73.75 | C7: =SUM(Results!G61:G63) -> 73.2 | D7: =SUM(Results!G64:G67) -> 74.85 | E7: =AVERAGE(B7:D7) -> 73.933333 | F7: =IF(E7>=80,"HD/D range",IF(E7>=70,"D range",IF(E7>=60,"C range",IF(E7>=50,"P range","At risk")))) -> D range
A8: STU0007 | B8: =SUM(Results!G68:G71) -> 52.45 | C8: =SUM(Results!G72:G74) -> 56.1 | D8: =SUM(Results!G75:G78) -> 52.05 | E8: =AVERAGE(B8:D8) -> 53.533333 | F8: =IF(E8>=80,"HD/D range",IF(E8>=70,"D range",IF(E8>=60,"C range",IF(E8>=50,"P range","At risk")))) -> P range
A9: STU0008 | B9: =SUM(Results!G79:G82) -> 76.55 | C9: =SUM(Results!G83:G85) -> 79.3 | D9: =SUM(Results!G86:G89) -> 80.35 | E9: =AVERAGE(B9:D9) -> 78.733333 | F9: =IF(E9>=80,"HD/D range",IF(E9>=70,"D range",IF(E9>=60,"C range",IF(E9>=50,"P range","At risk")))) -> D range
A10: STU0009 | B10: =SUM(Results!G90:G93) -> 65.2 | C10: =SUM(Results!G94:G96) -> 68.7 | D10: =SUM(Results!G97:G100) -> 71.4 | E10: =AVERAGE(B10:D10) -> 68.433333 | F10: =IF(E10>=80,"HD/D range",IF(E10>=70,"D range",IF(E10>=60,"C range",IF(E10>=50,"P range","At risk")))) -> C range
A11: STU0010 | B11: =SUM(Results!G101:G104) -> 67.1 | C11: =SUM(Results!G105:G107) -> 66.4 | D11: =SUM(Results!G108:G111) -> 66.05 | E11: =AVERAGE(B11:D11) -> 66.516667 | F11: =IF(E11>=80,"HD/D range",IF(E11>=70,"D range",IF(E11>=60,"C range",IF(E11>=50,"P range","At risk")))) -> C range
A12: STU0011 | B12: =SUM(Results!G112:G115) -> 52.05 | C12: =SUM(Results!G116:G118) -> 55.7 | D12: =SUM(Results!G119:G122) -> 55.8 | E12: =AVERAGE(B12:D12) -> 54.516667 | F12: =IF(E12>=80,"HD/D range",IF(E12>=70,"D range",IF(E12>=60,"C range",IF(E12>=50,"P range","At risk")))) -> P range
A13: STU0012 | B13: =SUM(Results!G123:G126) -> 63.6 | C13: =SUM(Results!G127:G129) -> 70.2 | D13: =SUM(Results!G130:G133) -> 61.75 | E13: =AVERAGE(B13:D13) -> 65.183333 | F13: =IF(E13>=80,"HD/D range",IF(E13>=70,"D range",IF(E13>=60,"C range",IF(E13>=50,"P range","At risk")))) -> C range
A14: STU0013 | B14: =SUM(Results!G134:G137) -> 67.45 | C14: =SUM(Results!G138:G140) -> 61.9 | D14: =SUM(Results!G141:G144) -> 59.4 | E14: =AVERAGE(B14:D14) -> 62.916667 | F14: =IF(E14>=80,"HD/D range",IF(E14>=70,"D range",IF(E14>=60,"C range",IF(E14>=50,"P range","At risk")))) -> C range
A15: STU0014 | B15: =SUM(Results!G145:G148) -> 85.5 | C15: =SUM(Results!G149:G151) -> 77.4 | D15: =SUM(Results!G152:G155) -> 79.85 | E15: =AVERAGE(B15:D15) -> 80.916667 | F15: =IF(E15>=80,"HD/D range",IF(E15>=70,"D range",IF(E15>=60,"C range",IF(E15>=50,"P range","At risk")))) -> HD/D range
A16: STU0015 | B16: =SUM(Results!G156:G159) -> 52.25 | C16: =SUM(Results!G160:G162) -> 57.2 | D16: =SUM(Results!G163:G166) -> 54.65 | E16: =AVERAGE(B16:D16) -> 54.7 | F16: =IF(E16>=80,"HD/D range",IF(E16>=70,"D range",IF(E16>=60,"C range",IF(E16>=50,"P range","At risk")))) -> P range
A17: STU0016 | B17: =SUM(Results!G167:G170) -> 63.1 | C17: =SUM(Results!G171:G173) -> 66.6 | D17: =SUM(Results!G174:G177) -> 60.3 | E17: =AVERAGE(B17:D17) -> 63.333333 | F17: =IF(E17>=80,"HD/D range",IF(E17>=70,"D range",IF(E17>=60,"C range",IF(E17>=50,"P range","At risk")))) -> C range
A18: STU0017 | B18: =SUM(Results!G178:G181) -> 66.15 | C18: =SUM(Results!G182:G184) -> 59.1 | D18: =SUM(Results!G185:G188) -> 59.15 | E18: =AVERAGE(B18:D18) -> 61.466667 | F18: =IF(E18>=80,"HD/D range",IF(E18>=70,"D range",IF(E18>=60,"C range",IF(E18>=50,"P range","At risk")))) -> C range
A19: STU0018 | B19: =SUM(Results!G189:G192) -> 61.55 | C19: =SUM(Results!G193:G195) -> 59.4 | D19: =SUM(Results!G196:G199) -> 60.55 | E19: =AVERAGE(B19:D19) -> 60.5 | F19: =IF(E19>=80,"HD/D range",IF(E19>=70,"D range",IF(E19>=60,"C range",IF(E19>=50,"P range","At risk")))) -> C range
A20: STU0019 | B20: =SUM(Results!G200:G203) -> 70.65 | C20: =SUM(Results!G204:G206) -> 69.4 | D20: =SUM(Results!G207:G210) -> 68.9 | E20: =AVERAGE(B20:D20) -> 69.65 | F20: =IF(E20>=80,"HD/D range",IF(E20>=70,"D range",IF(E20>=60,"C range",IF(E20>=50,"P range","At risk")))) -> C range
A21: STU0020 | B21: =SUM(Results!G211:G214) -> 79 | C21: =SUM(Results!G215:G217) -> 81.5 | D21: =SUM(Results!G218:G221) -> 80.4 | E21: =AVERAGE(B21:D21) -> 80.3 | F21: =IF(E21>=80,"HD/D range",IF(E21>=70,"D range",IF(E21>=60,"C range",IF(E21>=50,"P range","At risk")))) -> HD/D range
A22: STU0021 | B22: =SUM(Results!G222:G225) -> 73.5 | C22: =SUM(Results!G226:G228) -> 70 | D22: =SUM(Results!G229:G232) -> 70.5 | E22: =AVERAGE(B22:D22) -> 71.333333 | F22: =IF(E22>=80,"HD/D range",IF(E22>=70,"D range",IF(E22>=60,"C range",IF(E22>=50,"P range","At risk")))) -> D range
A23: STU0022 | B23: =SUM(Results!G233:G236) -> 73.45 | C23: =SUM(Results!G237:G239) -> 71 | D23: =SUM(Results!G240:G243) -> 77.05 | E23: =AVERAGE(B23:D23) -> 73.833333 | F23: =IF(E23>=80,"HD/D range",IF(E23>=70,"D range",IF(E23>=60,"C range",IF(E23>=50,"P range","At risk")))) -> D range
A24: STU0023 | B24: =SUM(Results!G244:G247) -> 66.05 | C24: =SUM(Results!G248:G250) -> 60.5 | D24: =SUM(Results!G251:G254) -> 61.5 | E24: =AVERAGE(B24:D24) -> 62.683333 | F24: =IF(E24>=80,"HD/D range",IF(E24>=70,"D range",IF(E24>=60,"C range",IF(E24>=50,"P range","At risk")))) -> C range
A25: STU0024 | B25: =SUM(Results!G255:G258) -> 70.4 | C25: =SUM(Results!G259:G261) -> 71 | D25: =SUM(Results!G262:G265) -> 76.7 | E25: =AVERAGE(B25:D25) -> 72.7 | F25: =IF(E25>=80,"HD/D range",IF(E25>=70,"D range",IF(E25>=60,"C range",IF(E25>=50,"P range","At risk")))) -> D range
A26: STU0025 | B26: =SUM(Results!G266:G269) -> 81.45 | C26: =SUM(Results!G270:G272) -> 83.2 | D26: =SUM(Results!G273:G276) -> 83.15 | E26: =AVERAGE(B26:D26) -> 82.6 | F26: =IF(E26>=80,"HD/D range",IF(E26>=70,"D range",IF(E26>=60,"C range",IF(E26>=50,"P range","At risk")))) -> HD/D range
A27: STU0026 | B27: =SUM(Results!G277:G280) -> 78.3 | C27: =SUM(Results!G281:G283) -> 79.3 | D27: =SUM(Results!G284:G287) -> 80.05 | E27: =AVERAGE(B27:D27) -> 79.216667 | F27: =IF(E27>=80,"HD/D range",IF(E27>=70,"D range",IF(E27>=60,"C range",IF(E27>=50,"P range","At risk")))) -> D range
A28: STU0027 | B28: =SUM(Results!G288:G291) -> 73.5 | C28: =SUM(Results!G292:G294) -> 71 | D28: =SUM(Results!G295:G298) -> 71.3 | E28: =AVERAGE(B28:D28) -> 71.933333 | F28: =IF(E28>=80,"HD/D range",IF(E28>=70,"D range",IF(E28>=60,"C range",IF(E28>=50,"P range","At risk")))) -> D range
A29: STU0028 | B29: =SUM(Results!G299:G302) -> 72.45 | C29: =SUM(Results!G303:G305) -> 76.2 | D29: =SUM(Results!G306:G309) -> 69.5 | E29: =AVERAGE(B29:D29) -> 72.716667 | F29: =IF(E29>=80,"HD/D range",IF(E29>=70,"D range",IF(E29>=60,"C range",IF(E29>=50,"P range","At risk")))) -> D range
A30: STU0029 | B30: =SUM(Results!G310:G313) -> 59.1 | C30: =SUM(Results!G314:G316) -> 59.5 | D30: =SUM(Results!G317:G320) -> 59.45 | E30: =AVERAGE(B30:D30) -> 59.35 | F30: =IF(E30>=80,"HD/D range",IF(E30>=70,"D range",IF(E30>=60,"C range",IF(E30>=50,"P range","At risk")))) -> P range
A31: STU0030 | B31: =SUM(Results!G321:G324) -> 64.15 | C31: =SUM(Results!G325:G327) -> 63.9 | D31: =SUM(Results!G328:G331) -> 65.25 | E31: =AVERAGE(B31:D31) -> 64.433333 | F31: =IF(E31>=80,"HD/D range",IF(E31>=70,"D range",IF(E31>=60,"C range",IF(E31>=50,"P range","At risk")))) -> C range
A32: STU0031 | B32: =SUM(Results!G332:G335) -> 77.9 | C32: =SUM(Results!G336:G338) -> 87.3 | D32: =SUM(Results!G339:G342) -> 85.7 | E32: =AVERAGE(B32:D32) -> 83.633333 | F32: =IF(E32>=80,"HD/D range",IF(E32>=70,"D range",IF(E32>=60,"C range",IF(E32>=50,"P range","At risk")))) -> HD/D range
A33: STU0032 | B33: =SUM(Results!G343:G346) -> 60.7 | C33: =SUM(Results!G347:G349) -> 63.1 | D33: =SUM(Results!G350:G353) -> 65.5 | E33: =AVERAGE(B33:D33) -> 63.1 | F33: =IF(E33>=80,"HD/D range",IF(E33>=70,"D range",IF(E33>=60,"C range",IF(E33>=50,"P range","At risk")))) -> C range
A34: STU0033 | B34: =SUM(Results!G354:G357) -> 82 | C34: =SUM(Results!G358:G360) -> 81.6 | D34: =SUM(Results!G361:G364) -> 82.3 | E34: =AVERAGE(B34:D34) -> 81.966667 | F34: =IF(E34>=80,"HD/D range",IF(E34>=70,"D range",IF(E34>=60,"C range",IF(E34>=50,"P range","At risk")))) -> HD/D range
A35: STU0034 | B35: =SUM(Results!G365:G368) -> 72.35 | C35: =SUM(Results!G369:G371) -> 68 | D35: =SUM(Results!G372:G375) -> 65.35 | E35: =AVERAGE(B35:D35) -> 68.566667 | F35: =IF(E35>=80,"HD/D range",IF(E35>=70,"D range",IF(E35>=60,"C range",IF(E35>=50,"P range","At risk")))) -> C range
A36: STU0035 | B36: =SUM(Results!G376:G379) -> 58.55 | C36: =SUM(Results!G380:G382) -> 56.9 | D36: =SUM(Results!G383:G386) -> 51.85 | E36: =AVERAGE(B36:D36) -> 55.766667 | F36: =IF(E36>=80,"HD/D range",IF(E36>=70,"D range",IF(E36>=60,"C range",IF(E36>=50,"P range","At risk")))) -> P range
A37: STU0036 | B37: =SUM(Results!G387:G390) -> 57.7 | C37: =SUM(Results!G391:G393) -> 64.3 | D37: =SUM(Results!G394:G397) -> 59.95 | E37: =AVERAGE(B37:D37) -> 60.65 | F37: =IF(E37>=80,"HD/D range",IF(E37>=70,"D range",IF(E37>=60,"C range",IF(E37>=50,"P range","At risk")))) -> C range
A38: STU0037 | B38: =SUM(Results!G398:G401) -> 54.35 | C38: =SUM(Results!G402:G404) -> 51.4 | D38: =SUM(Results!G405:G408) -> 50.7 | E38: =AVERAGE(B38:D38) -> 52.15 | F38: =IF(E38>=80,"HD/D range",IF(E38>=70,"D range",IF(E38>=60,"C range",IF(E38>=50,"P range","At risk")))) -> P range
A39: STU0038 | B39: =SUM(Results!G409:G412) -> 62.35 | C39: =SUM(Results!G413:G415) -> 63 | D39: =SUM(Results!G416:G419) -> 57.75 | E39: =AVERAGE(B39:D39) -> 61.033333 | F39: =IF(E39>=80,"HD/D range",IF(E39>=70,"D range",IF(E39>=60,"C range",IF(E39>=50,"P range","At risk")))) -> C range
A40: STU0039 | B40: =SUM(Results!G420:G423) -> 61 | C40: =SUM(Results!G424:G426) -> 59.5 | D40: =SUM(Results!G427:G430) -> 62.2 | E40: =AVERAGE(B40:D40) -> 60.9 | F40: =IF(E40>=80,"HD/D range",IF(E40>=70,"D range",IF(E40>=60,"C range",IF(E40>=50,"P range","At risk")))) -> C range
...

Sheet Assessment Map
A1: Subject Code | B1: Assessment Type | C1: Weight | D1: Contribution | E1: Early Assessment | F1: Hurdle | G1: SILOs | H1: SILO Theme Summary
A2: CSE1OOF | B2: CSE1OOF - Test | C2: 0.15 | D2: Individual | E2: Yes | F2: No | G2: SILO1, SILO2 | H2: SILO1: analysis/design/implementation compared with object-oriented modelling using objects that combine data structure and behaviour; SILO2: abstract data types and encapsulation to localise and minimise change
A3: CSE1OOF | B3: CSE1OOF - Practical demonstration | C3: 0.2 | D3: Individual | E3: No | F3: No | G3: SILO2, SILO3, SILO4 | H3: SILO2: abstract data types and encapsulation to localise and minimise change; SILO3: code sharing and reuse through object-oriented techniques to reduce development time; SILO4: object-oriented design and implementation of computer programs for real-life problems
A4: CSE1OOF | B4: CSE1OOF - Assignment | C4: 0.25 | D4: Individual | E4: No | F4: No | G4: SILO2, SILO3, SILO4 | H4: SILO2: abstract data types and encapsulation to localise and minimise change; SILO3: code sharing and reuse through object-oriented techniques to reduce development time; SILO4: object-oriented design and implementation of computer programs for real-life problems
A5: CSE1OOF | B5: CSE1OOF - Central examination | C5: 0.4 | D5: Individual | E5: No | F5: No | G5: SILO2, SILO4, SILO3, SILO1 | H5: SILO2: abstract data types and encapsulation to localise and minimise change; SILO4: object-oriented design and implementation of computer programs for real-life problems; SILO3: code sharing and reuse through object-oriented techniques to reduce development time; SILO1: analysis/design/implementation compared with object-oriented modelling using objects that combine data structure and behaviour
A6: CSE2ALG | B6: CSE2ALG - Test | C6: 0.2 | D6: Individual | E6: Yes | F6: No | G6: SILO1, SILO2, SILO3 | H6: SILO1: overall objectives of Algorithms and Data Structures; SILO2: identifying data structures and searching and sorting algorithms in computing contexts; SILO3: implementing data structures and searching and sorting algorithms in Java
A7: CSE2ALG | B7: CSE2ALG - Assignment | C7: 0.3 | D7: Individual | E7: No | F7: No | G7: SILO2, SILO3, SILO4, SILO5 | H7: SILO2: identifying data structures and searching and sorting algorithms in computing contexts; SILO3: implementing data structures and searching and sorting algorithms in Java; SILO4: comparing algorithms and data structures and applying suitable choices to problems; SILO5: designing, implementing, and evaluating Java solutions using appropriate performance measures
A8: CSE2ALG | B8: CSE2ALG - Central examination | C8: 0.5 | D8: Individual | E8: No | F8: No | G8: SILO1, SILO2, SILO3, SILO5 | H8: SILO1: overall objectives of Algorithms and Data Structures; SILO2: identifying data structures and searching and sorting algorithms in computing contexts; SILO3: implementing data structures and searching and sorting algorithms in Java; SILO5: designing, implementing, and evaluating Java solutions using appropriate performance measures
A9: CSE3CAP | B9: CSE3CAP - Oral presentation: Project Milestone Presentation | C9: 0.1 | D9: Group | E9: Yes | F9: No | G9: SILO3 | H9: SILO3: reporting project outcomes to technical and non-technical audiences and reflecting on feedback
A10: CSE3CAP | B10: CSE3CAP - Oral presentation: Final Project Presentation | C10: 0.2 | D10: Group | E10: No | F10: No | G10: SILO3 | H10: SILO3: reporting project outcomes to technical and non-technical audiences and reflecting on feedback
A11: CSE3CAP | B11: CSE3CAP - Assignment: Final written Project Report | C11: 0.35 | D11: Combined | E11: No | F11: No | G11: SILO2, SILO4 | H11: SILO2: industry standard technical solutions in software or cybersecurity practice; SILO4: professional system documentation and advanced technical reporting to industry standards
A12: CSE3CAP | B12: CSE3CAP - Assignment: Sprint Project management reports | C12: 0.35 | D12: Individual | E12: No | F12: No | G12: SILO1, SILO2 | H12: SILO1: advanced project management during substantive development implementation; SILO2: industry standard technical solutions in software or cybersecurity practice
